<mujoco model="manipulator">
    <compiler angle="radian"/>
    <option gravity="0 0 -9.81"/>

    <worldbody>
        <!-- Base -->
        <body name="base" pos="0 0 0.2">
            <inertial pos="0 0 0" mass="1.0" diaginertia="0.1 0.1 0.1"/>
            <joint name="base_joint" type="free"/>

            <!-- Link 1 -->
            <body name="link1" pos="0 0 0.2">
                <inertial pos="0 0 0" mass="2" diaginertia="0.1 0.1 0.1"/> <!-- Reduced mass -->
                <geom type="capsule" size="0.05 0.2" rgba="0.8 0.3 0.3 1"/>
                <joint name="joint1" type="hinge" axis="0 1 0" range="-180 180"/>

            <!-- Link 2 -->
            <body name="link2" pos="0 0 0.2">
                <inertial pos="0 0 0" mass="1" diaginertia="0.1 0.1 0.1"/> <!-- Reduced mass -->
                <geom type="capsule" size="0.05 0.2" rgba="0.3 0.3 0.8 1"/>
                <joint name="joint2" type="hinge" axis="0 1 0" range="-180 180"/>

                <!-- End effector -->
                <site name="end_effector" pos="0 0 0.0" size="0.02" rgba="0.8 0.8 0.8 1"/>
            </body>
            </body>
        </body>
    </worldbody>

    <!-- Actuators -->
    <actuator>
        <motor joint="joint1" ctrlrange="-1 1" gear="50"/> <!-- Increased gear for more sensitivity -->
        <motor joint="joint2" ctrlrange="-1 1" gear="50"/> <!-- Increased gear for more sensitivity -->
    </actuator>

</mujoco>
